<?xml version="1.0"?>
<robot name="basic_arm">

    <!-- Materials -->
    <material name="grey">
        <color rgba='0 0 0 1'/>
    </material>
    <material name="green">
        <color rgba="0 0.6 0 1"/>
    </material>
    <material name="red">
        <color rgba="0.6 0 0 1"/>
    </material>
    <material name="white">
        <color rgba="1 1 1 1"/>
    </material>

    <!-- Base link (scaled down) -->
    <link name="base_link">
        <visual>
            <geometry>
                <box size="0.07 0.11 0.13"/>
            </geometry>
            <origin xyz="0 0 0.065" rpy="0 0 0"/>
            <material name="green"/>
        </visual>
        <collision>
            <geometry>
                <box size="0.07 0.11 0.13"/>
            </geometry>
            <origin xyz="0 0 0.065" rpy="0 0 0"/>
        </collision>
        <inertial>
            <origin xyz="0 0 0.065" rpy="0 0 0"/>
            <mass value="1.0"/>
            <inertia ixx="0.001" ixy="0" ixz="0"
                     iyy="0.0008" iyz="0"
                     izz="0.0005"/>
        </inertial>
    </link>

    <!-- Base servo -->
    <link name="base_servo">
        <visual>
            <geometry>
                <cylinder radius="0.025" length="0.014"/>
            </geometry>
            <origin xyz="0 0 0" rpy="-1.5708 0 0"/>
            <material name="white"/>
        </visual>
        <collision>
            <geometry>
                <cylinder radius="0.025" length="0.014"/>
            </geometry>
            <origin xyz="0 0 0" rpy="-1.5708 0 0"/>
        </collision>
        <inertial>
            <origin xyz="0 0 0" rpy="0 0 0"/>
            <mass value="0.06"/>
            <inertia ixx="0.00003" ixy="0" ixz="0"
                     iyy="0.00003" iyz="0"
                     izz="0.000015"/>
        </inertial>
    </link>

    <!-- shoulder link -->
    <link name="shoulder_link">
        <visual>
            <geometry>
                <box size="0.04 0.08 0.04"/>
            </geometry>
            <origin xyz="0 0.036 0" rpy="0 0 0"/>
            <material name="grey"/>
        </visual>
        <collision>
            <geometry>
                <box size="0.04 0.08 0.04"/>
            </geometry>
            <origin xyz="0 0.036 0" rpy="0 0 0"/>
        </collision>
        <inertial>
            <origin xyz="0 0.036 0" rpy="0 0 0"/>
            <mass value="0.5"/>
            <inertia ixx="0.0005" ixy="0" ixz="0"
                     iyy="0.0003" iyz="0"
                     izz="0.0005"/>
        </inertial>
    </link>

    <!-- Shoulder_Servo -->
    <link name="Shoulder_servo">
        <visual>
            <geometry>
                <cylinder radius="0.02" length="0.018"/>
            </geometry>
            <origin xyz="0 0 0" rpy="0 0 0"/>
            <material name="white"/>
        </visual>
        <collision>
            <geometry>
                <cylinder radius="0.03" length="0.018"/>
            </geometry>
            <origin xyz="0 0 0" rpy="0 0 0"/>
        </collision>
        <inertial>
            <origin xyz="0 0 0" rpy="0 0 0"/>
            <mass value="0.08"/>
            <inertia ixx="0.00005" ixy="0" ixz="0"
                     iyy="0.00005" iyz="0"
                     izz="0.000025"/>
        </inertial>
    </link>

    <!-- elbow link -->
    <link name="elbow_link">
        <visual>
            <geometry>
                <box size="0.03 0.11 0.03"/>
            </geometry>
            <origin xyz="0 0.03 -0.018" rpy="0 0 0"/>
            <material name="grey"/>
        </visual>
        <collision>
            <geometry>
                <box size="0.03 0.11 0.03"/>
            </geometry>
            <origin xyz="0 0.03 -0.018" rpy="0 0 0"/>
        </collision>
        <inertial>
            <origin xyz="0 0.03 -0.018" rpy="0 0 0"/>
            <mass value="0.35"/>
            <inertia ixx="0.0003" ixy="0" ixz="0"
                     iyy="0.0002" iyz="0"
                     izz="0.0003"/>
        </inertial>
    </link>

    <!-- elbow_Servo -->
    <link name="elbow_servo">
        <visual>
            <geometry>
                <cylinder radius="0.02" length="0.014"/>
            </geometry>
            <origin xyz="0 0 0" rpy="0 0 0"/>
            <material name="white"/>
        </visual>
        <collision>
            <geometry>
                <cylinder radius="0.025" length="0.014"/>
            </geometry>
            <origin xyz="0 0 0" rpy="0 0 0"/>
        </collision>
        <inertial>
            <origin xyz="0 0 0" rpy="0 0 0"/>
            <mass value="0.05"/>
            <inertia ixx="0.00002" ixy="0" ixz="0"
                     iyy="0.00002" iyz="0"
                     izz="0.00001"/>
        </inertial>
    </link>

    <!-- wrist link -->
    <link name="wrist_link">
        <visual>
            <geometry>
                <box size="0.025 0.08 0.012"/>
            </geometry>
            <origin xyz="0 0.04 -0.006" rpy="0 0 0"/>
            <material name="grey"/>
        </visual>
        <collision>
            <geometry>
                <box size="0.025 0.08 0.012"/>
            </geometry>
            <origin xyz="0 0.04 -0.006" rpy="0 0 0"/>
        </collision>
        <inertial>
            <origin xyz="0 0.04 -0.006" rpy="0 0 0"/>
            <mass value="0.15"/>
            <inertia ixx="0.0001" ixy="0" ixz="0"
                     iyy="0.00005" iyz="0"
                     izz="0.0001"/>
        </inertial>
    </link>

    <!-- Right Base Servo -->
    <link name="right_base_servo">
        <visual>
            <geometry>
                <cylinder radius="0.025" length="0.014"/>
            </geometry>
            <origin xyz="0 0 0" rpy="-1.5708 0 0"/>
            <material name="white"/>
        </visual>
        <collision>
            <geometry>
                <cylinder radius="0.025" length="0.014"/>
            </geometry>
            <origin xyz="0 0 0" rpy="-1.5708 0 0"/>
        </collision>
        <inertial>
            <origin xyz="0 0 0" rpy="0 0 0"/>
            <mass value="0.06"/>
            <inertia ixx="0.00003" ixy="0" ixz="0"
                     iyy="0.00003" iyz="0"
                     izz="0.000015"/>
        </inertial>
    </link>

    <!-- right shoulder link -->
    <link name="right_shoulder_link">
        <visual>
            <geometry>
                <box size="0.04 0.08 0.04"/>
            </geometry>
            <origin xyz="0 -0.036 0" rpy="0 0 0"/>
            <material name="grey"/>
        </visual>
        <collision>
            <geometry>
                <box size="0.04 0.08 0.04"/>
            </geometry>
            <origin xyz="0 -0.036 0" rpy="0 0 0"/>
        </collision>
        <inertial>
            <origin xyz="0 -0.036 0" rpy="0 0 0"/>
            <mass value="0.5"/>
            <inertia ixx="0.0005" ixy="0" ixz="0"
                     iyy="0.0003" iyz="0"
                     izz="0.0005"/>
        </inertial>
    </link>

    <!-- right_shoulder_servo -->
    <link name="right_shoulder_servo">
        <visual>
            <geometry>
                <cylinder radius="0.02" length="0.018"/>
            </geometry>
            <origin xyz="0 0 0" rpy="0 0 0"/>
            <material name="white"/>
        </visual>
        <collision>
            <geometry>
                <cylinder radius="0.03" length="0.018"/>
            </geometry>
            <origin xyz="0 0 0" rpy="0 0 0"/>
        </collision>
        <inertial>
            <origin xyz="0 0 0" rpy="0 0 0"/>
            <mass value="0.08"/>
            <inertia ixx="0.00005" ixy="0" ixz="0"
                     iyy="0.00005" iyz="0"
                     izz="0.000025"/>
        </inertial>
    </link>

    <!-- right_elbow_link -->
    <link name="right_elbow_link">
        <visual>
            <geometry>
                <box size="0.03 0.11 0.03"/>
            </geometry>
            <origin xyz="0 -0.03 -0.018" rpy="0 0 0"/>
            <material name="grey"/>
        </visual>
        <collision>
            <geometry>
                <box size="0.03 0.11 0.03"/>
            </geometry>
            <origin xyz="0 -0.03 -0.018" rpy="0 0 0"/>
        </collision>
        <inertial>
            <origin xyz="0 -0.03 -0.018" rpy="0 0 0"/>
            <mass value="0.35"/>
            <inertia ixx="0.0003" ixy="0" ixz="0"
                     iyy="0.0002" iyz="0"
                     izz="0.0003"/>
        </inertial>
    </link>

    <!-- right_elbow_servo -->
    <link name="right_elbow_servo">
        <visual>
            <geometry>
                <cylinder radius="0.02" length="0.014"/>
            </geometry>
            <origin xyz="0 0 0" rpy="0 0 0"/>
            <material name="white"/>
        </visual>
        <collision>
            <geometry>
                <cylinder radius="0.025" length="0.014"/>
            </geometry>
            <origin xyz="0 0 0" rpy="0 0 0"/>
        </collision>
        <inertial>
            <origin xyz="0 0 0" rpy="0 0 0"/>
            <mass value="0.05"/>
            <inertia ixx="0.00002" ixy="0" ixz="0"
                     iyy="0.00002" iyz="0"
                     izz="0.00001"/>
        </inertial>
    </link>

    <!-- right_wrist_link -->
    <link name="right_wrist_link">
        <visual>
            <geometry>
                <box size="0.025 0.08 0.012"/>
            </geometry>
            <origin xyz="0 -0.04 -0.006" rpy="0 0 0"/>
            <material name="grey"/>
        </visual>
        <collision>
            <geometry>
                <box size="0.025 0.08 0.012"/>
            </geometry>
            <origin xyz="0 -0.04 -0.006" rpy="0 0 0"/>
        </collision>
        <inertial>
            <origin xyz="0 -0.04 -0.006" rpy="0 0 0"/>
            <mass value="0.15"/>
            <inertia ixx="0.0001" ixy="0" ixz="0"
                     iyy="0.00005" iyz="0"
                     izz="0.0001"/>
        </inertial>
    </link>

    <!-- head link (scaled down) -->
    <link name="head_link">
        <visual>
            <geometry>
                <sphere radius="0.03"/>
            </geometry>
            <origin xyz="0 0 0.03" rpy="0 0 0"/>
            <material name="red"/>
        </visual>
        <collision>
            <geometry>
                <sphere radius="0.03"/>
            </geometry>
            <origin xyz="0 0 0.03" rpy="0 0 0"/>
        </collision>
        <inertial>
            <origin xyz="0 0 0.03" rpy="0 0 0"/>
            <mass value="0.15"/>
            <inertia ixx="0.00004" ixy="0.0" ixz="0.0"
                    iyy="0.00004" iyz="0.0"
                    izz="0.00004"/>
        </inertial>
    </link>

    <!-- left_leg link (scaled down) -->
    <link name="left_leg_link">
        <visual>
            <geometry>
                <box  size="0.03 0.03 0.06"/>
            </geometry>
            <origin xyz="0 0 0.03" rpy="0 0 0"/>
            <material name="green"/>
        </visual>
        <collision>
            <geometry>
                <box size="0.03 0.03 0.06"/>
            </geometry>
            <origin xyz="0 0 0.03" rpy="0 0 0"/>
        </collision>
        <inertial>
            <origin xyz="0 0 0.03" rpy="0 0 0"/>
            <mass value="0.05"/>
            <inertia ixx="0.00001" ixy="0" ixz="0"
                     iyy="0.00001" iyz="0"
                     izz="0.00001"/>
        </inertial>
    </link>

    <!-- right_leg link (scaled down) -->
    <link name="right_leg_link">
        <visual>
            <geometry>
                <box  size="0.03 0.03 0.06"/>
            </geometry>
            <origin xyz="0 0 0.03" rpy="0 0 0"/>
            <material name="green"/>
        </visual>
        <collision>
            <geometry>
                <box size="0.03 0.03 0.06"/>
            </geometry>
            <origin xyz="0 0 0.03" rpy="0 0 0"/>
        </collision>
        <inertial>
            <origin xyz="0 0 0.03" rpy="0 0 0"/>
            <mass value="0.05"/>
            <inertia ixx="0.00001" ixy="0" ixz="0"
                     iyy="0.00001" iyz="0"
                     izz="0.00001"/>
        </inertial>
    </link>

    <!-- Joints (origins for base/head/legs also scaled down) -->
    <joint name="base_to_base_servo_joint" type="continuous">
        <parent link="base_link"/>
        <child link="base_servo"/>
        <origin xyz="0 0.055 0.09" rpy="0 0 0"/>
        <axis xyz="0 1 0"/>
    </joint>

    <joint name="base_servo_to_shoulder_joint" type="fixed">
        <parent link="base_servo"/>
        <child link="shoulder_link"/>
        <origin xyz="0 0.01 0" rpy="0 0 0"/>
    </joint>

    <joint name="shoulder_to_shoulder_servo_joint" type="continuous">
        <parent link="shoulder_link"/>
        <child link="Shoulder_servo"/>
        <origin xyz="0 0.06 -0.03" rpy="0 0 0"/>
        <axis xyz="0 0 1"/>
    </joint>

    <joint name="shoulder_servo_to_elbow_joint" type="fixed">
        <parent link="Shoulder_servo"/>
        <child link="elbow_link"/>
        <origin xyz="0 0 -0.005" rpy="0 0 0"/>
    </joint>

    <joint name="elbow_to_elbow_servo_joint" type="continuous">
        <parent link="elbow_link"/>
        <child link="elbow_servo"/>
        <origin xyz="0 0.06 -0.04" rpy="0 0 0"/>
        <axis xyz="0 0 1"/>
    </joint>

    <joint name="elbow_servo_to_wrist_joint" type="fixed">
        <parent link="elbow_servo"/>
        <child link="wrist_link"/>
        <origin xyz="0 0 -0.005" rpy="0 0 0"/>
    </joint>

    <joint name="base_to_right_base_servo_joint" type="continuous">
        <parent link="base_link"/>
        <child link="right_base_servo"/>
        <origin xyz="0 -0.055 0.09" rpy="0 0 0"/>
        <axis xyz="0 1 0"/>
    </joint>

    <joint name="right_base_servo_to_shoulder_joint" type="fixed">
        <parent link="right_base_servo"/>
        <child link="right_shoulder_link"/>
        <origin xyz="0 -0.01 0" rpy="0 0 0"/>
    </joint>  

    <joint name="right_shoulder_to_right_shoulder_servo_joint" type="continuous">
        <parent link="right_shoulder_link"/>
        <child link="right_shoulder_servo"/>
        <origin xyz="0 -0.06 -0.03" rpy="0 0 0"/>
        <axis xyz="0 0 1"/>
    </joint>

    <joint name="right_shoulder_servo_to_right_elbow_joint" type="fixed">
        <parent link="right_shoulder_servo"/>
        <child link="right_elbow_link"/>
        <origin xyz="0 0 -0.005" rpy="0 0 0"/>
    </joint>

    <joint name="right_elbow_to_right_elbow_servo_joint" type="continuous">
        <parent link="right_elbow_link"/>
        <child link="right_elbow_servo"/>
        <origin xyz="0 -0.06 -0.04" rpy="0 0 0"/>
        <axis xyz="0 0 1"/>
    </joint>

    <joint name="right_elbow_servo_to_right_wrist_joint" type="fixed">
        <parent link="right_elbow_servo"/>
        <child link="right_wrist_link"/>
        <origin xyz="0 0 -0.005" rpy="0 0 0"/>
    </joint>

    <joint name="base_to_head_joint" type="fixed">
       <parent link="base_link"/>
        <child link="head_link"/>
        <origin xyz="0 0 0.12" rpy="0 0 0"/>
    </joint>

    <joint name="base_to_left_leg_joint" type="fixed">
        <parent link="base_link"/>
        <child link="left_leg_link"/>
        <origin xyz="0 -0.03 -0.06" rpy="0 0 0"/>
    </joint>

    <joint name="base_to_right_leg_joint" type="fixed">
        <parent link="base_link"/>
        <child link="right_leg_link"/>
        <origin xyz="0 0.03 -0.06" rpy="0 0 0"/>
    </joint>
</robot>